<?xml version="1.0" encoding="utf-8"?>
<!-- This URDF was automatically created by SolidWorks to URDF Exporter! Originally created by Stephen Brawner (brawner@gmail.com) 
     Commit Version: 1.6.0-4-g7f85cfe  Build Version: 1.6.7995.38578
     For more information, please see http://wiki.ros.org/sw_urdf_exporter -->
<robot name="quad_wheel_robot_6" xmlns:xacro="http://www.ros.org/wiki/xacro">

  <xacro:property name="wheeldiam" value="0.05" />
  <xacro:property name="camera_link" value="0.02" /> <!-- Size of square 'camera' box -->
  <xacro:property name="height3" value="0.03" /> <!-- Size of square 'camera' box -->

  <link
    name="base_link">
    <inertial>
      <origin
        xyz="0.035777 -8.9781E-19 -2.4037E-18"
        rpy="0 0 0" />
      <mass
        value="0.37441" />
      <inertia
        ixx="0.00035771"
        ixy="-4.3022E-21"
        ixz="-1.3066E-20"
        iyy="0.0010529"
        iyz="-4.5897E-21"
        izz="0.00073547" />
    </inertial>
    <visual>
      <origin
        xyz="0 0 0"
        rpy="0 0 0" />
      <geometry>
        <mesh
          filename="package://quad_wheel_robot_6/meshes/base_link.STL" />
      </geometry>
      <material
        name="">
        <color
          rgba="0.79216 0.81961 0.93333 1" />
      </material>
    </visual>
    <collision>
      <origin
        xyz="0 0 0"
        rpy="0 0 0" />
      <geometry>
        <mesh
          filename="package://quad_wheel_robot_6/meshes/base_link.STL" />
      </geometry>
    </collision>
  </link>

  <link
    name="right_rear_wheel">
    <inertial>
      <origin
        xyz="3.8931E-19 0 6.9389E-18"
        rpy="0 0 0" />
      <mass
        value="0.032948" />
      <inertia
        ixx="5.1725E-06"
        ixy="1.2745E-54"
        ixz="-1.523E-38"
        iyy="5.1725E-06"
        iyz="-1.6431E-38"
        izz="6.8022E-06" />
    </inertial>
    <visual>
      <origin
        xyz="0 0 0"
        rpy="0 0 0" />
      <geometry>
        <cylinder radius="${wheeldiam/2}" length="0.02"/>
      </geometry>
      <material
        name="">
        <color
          rgba="0.79216 0.81961 0.93333 1" />
      </material>
    </visual>
    <collision>
      <origin
        xyz="0 0 0"
        rpy="0 0 0" />
      <geometry>
        <cylinder radius="${wheeldiam/2}" length="0.02"/>
      </geometry>
    </collision>
  </link>
  <joint
    name="right_rear_wheel_joint"
    type="continuous">
    <origin
      xyz="0 -0.0381 -0.03302"
      rpy="1.5708 0 0" />
    <parent
      link="base_link" />
    <child
      link="right_rear_wheel" />
    <axis
      xyz="0 0 -1" />
  </joint>
  <link
    name="left_rear_wheel">
    <inertial>
      <origin
        xyz="3.89312661068903E-19 0 -6.93889390390723E-18"
        rpy="0 0 0" />
      <mass
        value="0.0329481471208357" />
      <inertia
        ixx="5.17249447180973E-06"
        ixy="1.27447352890596E-54"
        ixz="1.0305020334644E-38"
        iyy="5.17249447180973E-06"
        iyz="-1.64312557597493E-38"
        izz="6.80218451087307E-06" />
    </inertial>
    <visual>
      <origin
        xyz="0 0 0"
        rpy="0 0 0" />
      <geometry>
        <cylinder radius="${wheeldiam/2}" length="0.02"/>
      </geometry>
      <material
        name="">
        <color
          rgba="0.792156862745098 0.819607843137255 0.933333333333333 1" />
      </material>
    </visual>
    <collision>
      <origin
        xyz="0 0 0"
        rpy="0 0 0" />
      <geometry>
        <cylinder radius="${wheeldiam/2}" length="0.02"/>
      </geometry>
    </collision>
  </link>
  <joint
    name="left_rear_wheel_joint"
    type="continuous">
    <origin
      xyz="0 0.0381 -0.03302"
      rpy="1.5708 0 0" />
    <parent
      link="base_link" />
    <child
      link="left_rear_wheel" />
    <axis
      xyz="0 0 -1" />
  </joint>
  <link
    name="right_front_wheel">
    <inertial>
      <origin
        xyz="-1.3878E-17 0 0"
        rpy="0 0 0" />
      <mass
        value="0.032948" />
      <inertia
        ixx="5.1725E-06"
        ixy="2.5489E-54"
        ixz="-1.7929E-22"
        iyy="5.1725E-06"
        iyz="-1.6431E-38"
        izz="6.8022E-06" />
    </inertial>
    <visual>
      <origin
        xyz="0 0 0"
        rpy="0 0 0" />
      <geometry>
        <cylinder radius="${wheeldiam/2}" length="0.02"/>
      </geometry>
      <material
        name="">
        <color
          rgba="0.79216 0.81961 0.93333 1" />
      </material>
    </visual>
    <collision>
      <origin
        xyz="0 0 0"
        rpy="0 0 0" />
      <geometry>
        <cylinder radius="${wheeldiam/2}" length="0.02"/>
      </geometry>
    </collision>
  </link>
  <joint
    name="right_front_wheel_joint"
    type="continuous">
    <origin
      xyz="0.0762 -0.0381 -0.03302"
      rpy="1.5708 0 0" />
    <parent
      link="base_link" />
    <child
      link="right_front_wheel" />
    <axis
      xyz="0 0 -1" />
  </joint>
  <link
    name="left_front_wheel">
    <inertial>
      <origin
        xyz="0 0 -6.93889390390723E-18"
        rpy="0 0 0" />
      <mass
        value="0.0329481471208357" />
      <inertia
        ixx="5.17249447180973E-06"
        ixy="1.27447352890596E-54"
        ixz="1.7928864050216E-22"
        iyy="5.17249447180973E-06"
        iyz="-1.64312557597493E-38"
        izz="6.80218451087308E-06" />
    </inertial>
    <visual>
      <origin
        xyz="0 0 0"
        rpy="0 0 0" />
      <geometry>
        <cylinder radius="${wheeldiam/2}" length="0.02"/>
      </geometry>
      <material
        name="">
        <color
          rgba="0.792156862745098 0.819607843137255 0.933333333333333 1" />
      </material>
    </visual>
    <collision>
      <origin
        xyz="0 0 0"
        rpy="0 0 0" />
      <geometry>
        <cylinder radius="${wheeldiam/2}" length="0.02"/>
      </geometry>
    </collision>
  </link>
  <joint
    name="left_front_wheel_joint"
    type="continuous">
    <origin
      xyz="0.0762 0.0381 -0.03302"
      rpy="1.5708 0 0" />
    <parent
      link="base_link" />
    <child
      link="left_front_wheel" />
    <axis
      xyz="0 0 -1" />
  </joint>

  <!-- Gazebo plugin for ROS Control -->
  <xacro:macro name="wheel_transmission" params="name">
    <transmission name="${name}_trans">
      <type>transmission_interface/SimpleTransmission</type>
      <joint name="${name}_joint">
        <hardwareInterface>hardware_interface/VelocityJointInterface</hardwareInterface>
      </joint>
      <actuator name="${name}_motor">
        <mechanicalReduction>1</mechanicalReduction>
      </actuator>
    </transmission>
  </xacro:macro>

  <xacro:wheel_transmission name="left_rear_wheel"/>
  <xacro:wheel_transmission name="right_rear_wheel"/>
  <xacro:wheel_transmission name="left_front_wheel"/>
  <xacro:wheel_transmission name="right_front_wheel"/>

  <!-- Camera -->
  <link name="camera_link">
    <collision>
      <origin xyz="0 0 0" rpy="0 0 0"/>
      <geometry>
    <box size="${camera_link} ${camera_link} ${camera_link}"/>
      </geometry>
    </collision>

    <visual>
      <origin xyz="0 0 0" rpy="0 0 0"/>
      <geometry>
        <box size="${camera_link} ${camera_link} ${camera_link}"/>
      </geometry>
      <material name="red"/>
    </visual>

    <inertial>
      <mass value="1e-5" />
      <origin xyz="0 0 0" rpy="0 0 0"/>
      <inertia ixx="1e-6" ixy="0" ixz="0" iyy="1e-6" iyz="0" izz="1e-6" />
    </inertial>
  </link>

  <joint name="camera_joint" type="fixed">
    <axis xyz="0 1 0" />
    <origin xyz="${camera_link} 0 ${height3}" rpy="0 0 0"/>
    <parent link="base_link"/>
    <child link="camera_link"/>
  </joint>

   <!-- camera -->
  <gazebo reference="camera_link">
    <sensor type="camera" name="camera1">
      <update_rate>30.0</update_rate>
      <camera name="head">
        <horizontal_fov>1.3962634</horizontal_fov>
        <image>
          <width>800</width>
          <height>800</height>
          <format>R8G8B8</format>
        </image>
        <clip>
          <near>0.02</near>
          <far>300</far>
        </clip>
        <noise>
          <type>gaussian</type>
          <!-- Noise is sampled independently per pixel on each frame.
               That pixel's noise value is added to each of its color
               channels, which at that point lie in the range [0,1]. -->
          <mean>0.0</mean>
          <stddev>0.007</stddev>
        </noise>
      </camera>
      <plugin name="camera_controller" filename="libgazebo_ros_camera.so">
        <alwaysOn>true</alwaysOn>
        <updateRate>0.0</updateRate>
        <cameraName>rrbot/camera1</cameraName>
        <imageTopicName>image_raw</imageTopicName>
        <cameraInfoTopicName>camera_info</cameraInfoTopicName>
        <frameName>camera_link</frameName>
        <hackBaseline>0.07</hackBaseline>
        <distortionK1>0.0</distortionK1>
        <distortionK2>0.0</distortionK2>
        <distortionK3>0.0</distortionK3>
        <distortionT1>0.0</distortionT1>
        <distortionT2>0.0</distortionT2>
      </plugin>
    </sensor>
  </gazebo>

  <gazebo>
    <plugin name="gazebo_ros_control" filename="libgazebo_ros_control.so">
      <robotNamespace>/</robotNamespace>
    </plugin>
  </gazebo>

</robot>